func fetchData() async throws -> Data {
    let url = URL(string: "https://api.example.com/data")!
    let (data, _) = try await URLSession.shared.data(from: url)
    return data
}

Task { 
    do {
        let data = try await fetchData()
        // Process data
    } catch {
        print("Error fetching data: \(error)")
        // Handle error appropriately.  This is where the bug lies.  Consider the case where fetchData throws an error and execution jumps here.
        // The current error handling is insufficient.  It prints the error but does not offer any mechanism to retry, show an alert to the user, etc.
    }
}